Workbook

Sheet 投资估算表
A1: 德阳市大宗货物（旌北新区）物流基地项目（黄许一期）— 投资估算表
A2: 金额单位：万元 | 修订版：依据设计院2026.05.27总图t8版 | 编制日期：2026年6月
A4: 序号 | B4: 工程或费用名称 | C4: 估算价值（万元） | H4: 技术经济指标 | K4: 备注 | L4: 比例 （%）
C5: 建筑工程费 | D5: 安装工程费 | E5: 设备购置费 | F5: 其他费用 | G5: 合计 | H5: 单位 | I5: 数量 | J5: 单位价值 （元/单位）
A6: 一 | B6: 工程费用 | C6: =G7 | D6: =G23 | E6: =G29 | F6: =G34 | G6: =C6+D6+E6+F6 | L6: 0.729
A7: 1 | B7: 建筑工程 | G7: =SUM(G8:G22) | L7: 0.495
A8: 1.1 | B8: 大宗物流仓 1# | C8: =G8 | G8: =I8*J8/10000 | H8: ㎡ | I8: 23040 | J8: 1550 | K8: 2F钢结构，含坡道+货梯土建，最大单体
A9: 1.2 | B9: 大宗物流仓 2# | C9: =G9 | G9: =I9*J9/10000 | H9: ㎡ | I9: 23040 | J9: 1530 | K9: 2F钢结构，最大单体
A10: 1.3 | B10: 大宗物流仓 3# | C10: =G10 | G10: =I10*J10/10000 | H10: ㎡ | I10: 8160 | J10: 1580 | K10: 2F钢结构，小单体单价略高
A11: 1.4 | B11: 大宗物流仓 4# | C11: =G11 | G11: =I11*J11/10000 | H11: ㎡ | I11: 11952 | J11: 1550 | K11: 2F钢结构
A12: 1.5 | B12: 大宗物流仓 5# | C12: =G12 | G12: =I12*J12/10000 | H12: ㎡ | I12: 17424 | J12: 1530 | K12: 2F钢结构
A13: 1.6 | B13: 大宗物流仓 6# | C13: =G13 | G13: =I13*J13/10000 | H13: ㎡ | I13: 16128 | J13: 1530 | K13: 2F钢结构
A14: 1.7 | B14: 大宗物流仓 7# | C14: =G14 | G14: =I14*J14/10000 | H14: ㎡ | I14: 16128 | J14: 1530 | K14: 2F钢结构
A15: 1.8 | B15: 大宗物流仓 8# | C15: =G15 | G15: =I15*J15/10000 | H15: ㎡ | I15: 13440 | J15: 1530 | K15: 2F钢结构
A16: 1.9 | B16: 大宗物流仓 11# | C16: =G16 | G16: =I16*J16/10000 | H16: ㎡ | I16: 6912 | J16: 1580 | K16: 2F钢结构，小单体
A17: 1.10 | B17: 冷库 9# | C17: =G17 | G17: =I17*J17/10000 | H17: ㎡ | I17: 13440 | J17: 6800 | K17: 2F，NH₃/CO₂复叠制冷，150mm PIR保温
A18: 1.11 | B18: 中转仓 10# | C18: =G18 | G18: =I18*J18/10000 | H18: ㎡ | I18: 6912 | J18: 1620 | K18: 2F钢结构，含双侧月台
A19: 1.12 | B19: 机修间 | C19: =G19 | G19: =I19*J19/10000 | H19: ㎡ | I19: 1008 | J19: 2200 | K19: 1F钢结构
... A22: 1.15 | B22: 防火涂料增项（一级耐火） | C22: =G22 | G22: =I22*J22/10000 | H22: ㎡ | I22: 158819 | J22: 45 | K22: 厚涂型防火涂料，钢结构一级耐火
A23: 2 | B23: 安装工程 | G23: =SUM(G24:G28) | L23: 0.077
A24: 2.1 | B24: 给排水工程 | D24: =G24 | G24: =I24*J24/10000 | H24: ㎡ | I24: 158819 | J24: 35 | K24: 含雨污水管网、给水系统
A25: 2.2 | B25: 供配电工程 | D25: =G25 | G25: =I25*J25/10000 | H25: ㎡ | I25: 158819 | J25: 88 | K25: 含高低压配电、照明，冷库用电负荷增加
A26: 2.3 | B26: 暖通工程 | D26: =G26 | G26: =I26*J26/10000 | H26: ㎡ | I26: 158819 | J26: 32 | K26: 通风、排烟、冷库制冷管道
A27: 2.4 | B27: 消防工程 | D27: =G27 | G27: =I27*J27/10000 | H27: ㎡ | I27: 158819 | J27: 125 | K27: 一级耐火增项：含消火栓、ESFR喷淋、报警
A28: 2.5 | B28: 智能化工程 | D28: =G28 | G28: =I28*J28/10000 | H28: ㎡ | I28: 158819 | J28: 42 | K28: 含监控、网络、WMS基础设施
A29: 3 | B29: 设备购置费 | G29: =SUM(G30:G33) | L29: 0.105
A30: 3.1 | B30: 物流设备 | E30: =G30 | G30: =I30*J30/10000 | H30: 项 | I30: 1 | J30: 36060000 | K30: 叉车+货架+货梯+托盘+地磅等（详见5.2.2）
A31: 3.2 | B31: 冷链设备 | E31: =G31 | G31: =I31*J31/10000 | H31: 项 | I31: 1 | J31: 28320000 | K31: 压缩机组+冷风机+冷凝器+冷库门（详见5.2.3）
A32: 3.3 | B32: 信息化设备 | E32: =G32 | G32: =I32*J32/10000 | H32: 项 | I32: 1 | J32: 6560000 | K32: 服务器+网络+监控+大屏+UPS（详见5.2.4）
A33: 3.4 | B33: 充电桩 | E33: =G33 | G33: =I33*J33/10000 | H33: 台 | I33: 48 | J33: 4000 | K33: 预留15%充电车位
A34: 4 | B34: 室外配套工程 | G34: =SUM(G35:G43) | L34: 0.051
A35: 4.1 | B35: 道路及硬化 | F35: =G35 | G35: =I35*J35/10000 | H35: ㎡ | I35: 72000 | J35: 285 | K35: 含主干道(沥青)+次干道+支路(混凝土)
A36: 4.2 | B36: 绿化工程 | F36: =G36 | G36: =I36*J36/10000 | H36: ㎡ | I36: 19650 | J36: 82 | K36: 含行道树、绿地、海绵设施
A37: 4.3 | B37: 货车停车场 | F37: =G37 | G37: =I37*J37/10000 | H37: ㎡ | I37: 10100 | J37: 320 | K37: C35重载混凝土
A38: 4.4 | B38: 给排水外网 | F38: =G38 | G38: =I38*J38/10000 | H38: 项 | I38: 1 | J38: 5200000 | K38: 接入市政管网，含消防管网
A39: 4.5 | B39: 供配电外线 | F39: =G39 | G39: =I39*J39/10000 | H39: 项 | I39: 1 | J39: 3500000 | K39: 10kV外线+箱变
A40: 4.6 | B40: 围墙及大门 | F40: =G40 | G40: =I40*J40/10000 | H40: m | I40: 1800 | J40: 1200 | K40: 2.5m砖砌+铁艺，4座电动门
A41: 4.7 | B41: 海绵城市增量 | F41: =G41 | G41: =I41*J41/10000 | H41: 项 | I41: 1 | J41: 1800000 | K41: 雨水花园+下凹绿地+透水铺装+调蓄池
A42: 4.8 | B42: 绿色建筑增量 | F42: =G42 | G42: =I42*J42/10000 | H42: 项 | I42: 1 | J42: 1200000 | K42: 一星级绿色建筑增量成本
A43: 4.9 | B43: 室外综合管沟 | F43: =G43 | G43: =I43*J43/10000 | H43: m | I43: 2800 | J43: 350 | K43: 给水/消防/电力/通信共沟
...

Sheet 编制说明
A1: 投资估算编制说明（修订版）
A3: 一、 | B3: 编制依据
B4: 1. 本项目总平面图（黄许一期，2026.05.27 t8版）及建构筑物一览表——设计院施工图阶段设计文件
B5: 2. 德阳市2025年上半年建设工程造价指数（183.16，以2005年为基期）
B6: 3. 《四川省建设工程工程量清单计价定额》（2020版）
B7: 4. 国家发展改革委《建设项目投资估算编审规程》（CECA/GC1）
B8: 5. 《物资集散中心和陆港仓库建设规范》（T/SDTLA 0001-2024）
B9: 6. 同类项目：德阳蓉欧冷链运营中心（已建成）、芜湖裕溪口多式联运基地（2025年招标）、德阳临港制造产业园（在建）
B10: 7. 设备价格：2025年市场询价及同类项目采购参考
A12: 二、 | B12: 主要取费标准
B13: · 建设单位管理费：财建〔2016〕504号，阶梯费率 → 530万元
B14: · 工程监理费：发改价格〔2007〕670号插入法 → 716万元
B15: · 勘察设计费：工程费用×2.5% → 1,193万元
B16: · 基本预备费：(工程费用+工程建设其他费)×8% → 4,554万元
B17: · 土地取得费：按180,000元/亩综合价（含出让金及税费），295亩 → 5,310万元
B18: · 建设期利息：按融资30,000万元×2.8%×2年（平均） → 1,680万元
B19: · 城市基础设施配套费：158,819㎡×20元/㎡ → 318万元
A21: 三、 | B21: 主要单价指标来源
B22: · 2F钢结构物流仓 1,530~1,580元/㎡ — 增加二层楼面+货梯坡道土建+一级耐火，较单层方案+110~160元/㎡
B23: · 2F冷库（含保温+NH₃/CO₂复叠制冷）6,800元/㎡ — 规模13,440㎡，较旧版+300元/㎡
B24: · 2F中转仓（含双侧月台）1,620元/㎡
B25: · 消防工程（一级耐火）125元/㎡ — 一级耐火较二级+25元/㎡
B26: · 海绵城市增量 180万元 — 雨水花园+下凹绿地+透水铺装+调蓄池
B27: · 绿色建筑增量 120万元 — 一星级绿色建筑（GB/T 50378-2019）
B28: · 防火涂料增项 45元/㎡ — 厚涂型，钢结构一级耐火（钢柱≥3h）
A30: 四、 | B30: 与旧版主要差异
B31: ① 仓库由单层→双层钢结构门式刚架（1F→2F，建筑高度23.8m）
B32: ② 耐火等级由二级→一级（消防工程单价100→125元/㎡，新增防火涂料715万元）
B33: ③ 冷库面积由8,000→13,440㎡（+68%），设备规模相应增加
B34: ④ 新增20台货梯（5t贯通式，500万元），充电桩48台（19万元）
B35: ⑤ 新增海绵城市（180万元）+ 绿色建筑（120万元）+ BIM（127万元）
B36: ⑥ 项目总资金由52,400→65,656万元，增幅约25.3%
A38: 五、 | B38: 待确认事项
B39: ① 土地出让金实际价格（暂按18万/亩综合价，需以自然资源部门评估价为准）
B40: ② 冷库NH₃/CO₂复叠制冷系统的最终设备选型和价格（暂按国产+进口组合估算）
B41: ③ 详勘后地基基础形式（如有软土层需增加桩基费用约500~800万元）
B42: ④ 建设期利息按融资3亿元×2.8%×2年估算，实际利率以融资方案确定
B43: ⑤ BIM应用深度（暂按基础建模+施工应用，若增加运维BIM需追加约80万元）

Sheet 投资构成分析
A1: 德阳物流基地（黄许一期）— 投资构成分析
A3: 构成项目 | B3: 金额（万元） | C3: 占比
A4: 一、工程费用 | B4: =投资估算表!G6 | C4: =投资估算表!G6/投资估算表!G64
A5: 1. 建筑工程 | B5: =投资估算表!G7 | C5: =投资估算表!G7/投资估算表!G64
A6: 2. 安装工程 | B6: =投资估算表!G23 | C6: =投资估算表!G23/投资估算表!G64
A7: 3. 设备购置费 | B7: =投资估算表!G29 | C7: =投资估算表!G29/投资估算表!G64
A8: 4. 室外配套工程 | B8: =投资估算表!G34 | C8: =投资估算表!G34/投资估算表!G64
A9: 二、工程建设其他费 | B9: =投资估算表!G44 | C9: =投资估算表!G44/投资估算表!G64
A10: 三、预备费 | B10: =投资估算表!G58 | C10: =投资估算表!G58/投资估算表!G64
A11: 四、建设期利息 | B11: =投资估算表!G60 | C11: =投资估算表!G60/投资估算表!G64
A12: 五、铺底流动资金 | B12: =投资估算表!G63 | C12: =投资估算表!G63/投资估算表!G64
A13: 项目总资金 | B13: =投资估算表!G64 | C13: 1
A16: 主要技术经济指标
A17: 建设用地面积 | B17: 196,481 ㎡（约295亩）
A18: 总建筑面积 | B18: 158,819 ㎡
A19: 计容建筑面积 | B19: 317,411 ㎡
A20: 容积率 | B20: 1.615
A21: 建筑密度 | B21: 40.99%
A22: 绿地率 | B22: 10.00%
A23: 亩均投资 | B23: 222.5 万元/亩
A24: 单位建筑面积综合投资 | B24: 4,134 元/㎡
